[2024-04-19T02:02:18.900+0000] {taskinstance.py:1956} INFO - Dependencies all met for dep_context=non-requeueable deps ti=<TaskInstance: MLOP_pro.create_newfile_task manual__2024-04-19T02:01:59.491504+00:00 [queued]>
[2024-04-19T02:02:18.903+0000] {taskinstance.py:1956} INFO - Dependencies all met for dep_context=requeueable deps ti=<TaskInstance: MLOP_pro.create_newfile_task manual__2024-04-19T02:01:59.491504+00:00 [queued]>
[2024-04-19T02:02:18.904+0000] {taskinstance.py:2170} INFO - Starting attempt 1 of 1
[2024-04-19T02:02:18.911+0000] {taskinstance.py:2191} INFO - Executing <Task(PythonOperator): create_newfile_task> on 2024-04-19 02:01:59.491504+00:00
[2024-04-19T02:02:18.925+0000] {standard_task_runner.py:60} INFO - Started process 1939 to run task
[2024-04-19T02:02:18.928+0000] {standard_task_runner.py:87} INFO - Running: ['***', 'tasks', 'run', 'MLOP_pro', 'create_newfile_task', 'manual__2024-04-19T02:01:59.491504+00:00', '--job-id', '28', '--raw', '--subdir', 'DAGS_FOLDER/***.py', '--cfg-path', '/tmp/tmpj7v2g32z']
[2024-04-19T02:02:18.931+0000] {standard_task_runner.py:88} INFO - Job 28: Subtask create_newfile_task
[2024-04-19T02:02:18.961+0000] {task_command.py:423} INFO - Running <TaskInstance: MLOP_pro.create_newfile_task manual__2024-04-19T02:01:59.491504+00:00 [running]> on host 33cbb430d6d6
[2024-04-19T02:02:18.997+0000] {taskinstance.py:2480} INFO - Exporting env vars: AIRFLOW_CTX_DAG_OWNER='Group_9' AIRFLOW_CTX_DAG_ID='MLOP_pro' AIRFLOW_CTX_TASK_ID='create_newfile_task' AIRFLOW_CTX_EXECUTION_DATE='2024-04-19T02:01:59.491504+00:00' AIRFLOW_CTX_TRY_NUMBER='1' AIRFLOW_CTX_DAG_RUN_ID='manual__2024-04-19T02:01:59.491504+00:00'
[2024-04-19T02:02:18.999+0000] {taskinstance.py:2698} ERROR - Task failed with exception
Traceback (most recent call last):
  File "/home/airflow/.local/lib/python3.8/site-packages/airflow/models/taskinstance.py", line 433, in _execute_task
    result = execute_callable(context=context, **execute_callable_kwargs)
  File "/home/airflow/.local/lib/python3.8/site-packages/airflow/operators/python.py", line 199, in execute
    return_value = self.execute_callable()
  File "/home/airflow/.local/lib/python3.8/site-packages/airflow/operators/python.py", line 216, in execute_callable
    return self.python_callable(*self.op_args, **self.op_kwargs)
  File "/opt/airflow/dags/src/create.py", line 11, in create_newfile
    with xw.App(visible=False) as app:
  File "/home/airflow/.local/lib/python3.8/site-packages/xlwings/main.py", line 311, in __init__
    self.impl = engines.active.apps.add(
AttributeError: 'NoneType' object has no attribute 'apps'
[2024-04-19T02:02:19.008+0000] {taskinstance.py:1138} INFO - Marking task as FAILED. dag_id=MLOP_pro, task_id=create_newfile_task, execution_date=20240419T020159, start_date=20240419T020218, end_date=20240419T020219
[2024-04-19T02:02:19.012+0000] {standard_task_runner.py:107} ERROR - Failed to execute job 28 for task create_newfile_task ('NoneType' object has no attribute 'apps'; 1939)
[2024-04-19T02:02:19.032+0000] {local_task_job_runner.py:234} INFO - Task exited with return code 1
[2024-04-19T02:02:19.045+0000] {taskinstance.py:3280} INFO - 0 downstream tasks scheduled from follow-on schedule check
