[2024-04-19T01:03:01.689+0000] {taskinstance.py:1956} INFO - Dependencies all met for dep_context=non-requeueable deps ti=<TaskInstance: MLOP_pro.create_newfile_task manual__2024-04-19T01:02:18.629564+00:00 [queued]>
[2024-04-19T01:03:01.693+0000] {taskinstance.py:1956} INFO - Dependencies all met for dep_context=requeueable deps ti=<TaskInstance: MLOP_pro.create_newfile_task manual__2024-04-19T01:02:18.629564+00:00 [queued]>
[2024-04-19T01:03:01.693+0000] {taskinstance.py:2170} INFO - Starting attempt 1 of 1
[2024-04-19T01:03:01.699+0000] {taskinstance.py:2191} INFO - Executing <Task(PythonOperator): create_newfile_task> on 2024-04-19 01:02:18.629564+00:00
[2024-04-19T01:03:01.704+0000] {standard_task_runner.py:60} INFO - Started process 786 to run task
[2024-04-19T01:03:01.707+0000] {standard_task_runner.py:87} INFO - Running: ['***', 'tasks', 'run', 'MLOP_pro', 'create_newfile_task', 'manual__2024-04-19T01:02:18.629564+00:00', '--job-id', '10', '--raw', '--subdir', 'DAGS_FOLDER/src/***.py', '--cfg-path', '/tmp/tmpaj7eaop5']
[2024-04-19T01:03:01.709+0000] {standard_task_runner.py:88} INFO - Job 10: Subtask create_newfile_task
[2024-04-19T01:03:01.751+0000] {task_command.py:423} INFO - Running <TaskInstance: MLOP_pro.create_newfile_task manual__2024-04-19T01:02:18.629564+00:00 [running]> on host 33cbb430d6d6
[2024-04-19T01:03:01.789+0000] {taskinstance.py:2480} INFO - Exporting env vars: AIRFLOW_CTX_DAG_OWNER='Group_9' AIRFLOW_CTX_DAG_ID='MLOP_pro' AIRFLOW_CTX_TASK_ID='create_newfile_task' AIRFLOW_CTX_EXECUTION_DATE='2024-04-19T01:02:18.629564+00:00' AIRFLOW_CTX_TRY_NUMBER='1' AIRFLOW_CTX_DAG_RUN_ID='manual__2024-04-19T01:02:18.629564+00:00'
[2024-04-19T01:03:01.790+0000] {taskinstance.py:2698} ERROR - Task failed with exception
Traceback (most recent call last):
  File "/home/airflow/.local/lib/python3.8/site-packages/airflow/models/taskinstance.py", line 433, in _execute_task
    result = execute_callable(context=context, **execute_callable_kwargs)
  File "/home/airflow/.local/lib/python3.8/site-packages/airflow/operators/python.py", line 199, in execute
    return_value = self.execute_callable()
  File "/home/airflow/.local/lib/python3.8/site-packages/airflow/operators/python.py", line 216, in execute_callable
    return self.python_callable(*self.op_args, **self.op_kwargs)
  File "/opt/airflow/dags/src/create.py", line 11, in create_newfile
    with xw.App(visible=False) as app:
  File "/home/airflow/.local/lib/python3.8/site-packages/xlwings/main.py", line 311, in __init__
    self.impl = engines.active.apps.add(
AttributeError: 'NoneType' object has no attribute 'apps'
[2024-04-19T01:03:01.795+0000] {taskinstance.py:1138} INFO - Marking task as FAILED. dag_id=MLOP_pro, task_id=create_newfile_task, execution_date=20240419T010218, start_date=20240419T010301, end_date=20240419T010301
[2024-04-19T01:03:01.800+0000] {standard_task_runner.py:107} ERROR - Failed to execute job 10 for task create_newfile_task ('NoneType' object has no attribute 'apps'; 786)
[2024-04-19T01:03:01.811+0000] {local_task_job_runner.py:234} INFO - Task exited with return code 1
[2024-04-19T01:03:01.824+0000] {taskinstance.py:3280} INFO - 0 downstream tasks scheduled from follow-on schedule check
