[2024-04-19T02:17:49.168+0000] {taskinstance.py:1159} INFO - Dependencies all met for dep_context=non-requeueable deps ti=<TaskInstance: MLOP_pro.create_newfile_task manual__2024-04-19T02:17:29.741995+00:00 [queued]>
[2024-04-19T02:17:49.173+0000] {taskinstance.py:1159} INFO - Dependencies all met for dep_context=requeueable deps ti=<TaskInstance: MLOP_pro.create_newfile_task manual__2024-04-19T02:17:29.741995+00:00 [queued]>
[2024-04-19T02:17:49.173+0000] {taskinstance.py:1361} INFO - Starting attempt 1 of 1
[2024-04-19T02:17:49.181+0000] {taskinstance.py:1382} INFO - Executing <Task(PythonOperator): create_newfile_task> on 2024-04-19 02:17:29.741995+00:00
[2024-04-19T02:17:49.191+0000] {standard_task_runner.py:57} INFO - Started process 147 to run task
[2024-04-19T02:17:49.194+0000] {standard_task_runner.py:84} INFO - Running: ['***', 'tasks', 'run', 'MLOP_pro', 'create_newfile_task', 'manual__2024-04-19T02:17:29.741995+00:00', '--job-id', '7', '--raw', '--subdir', 'DAGS_FOLDER/***.py', '--cfg-path', '/tmp/tmpukbwt9yj']
[2024-04-19T02:17:49.196+0000] {standard_task_runner.py:85} INFO - Job 7: Subtask create_newfile_task
[2024-04-19T02:17:49.222+0000] {task_command.py:416} INFO - Running <TaskInstance: MLOP_pro.create_newfile_task manual__2024-04-19T02:17:29.741995+00:00 [running]> on host d35862d43e4d
[2024-04-19T02:17:49.276+0000] {taskinstance.py:1662} INFO - Exporting env vars: AIRFLOW_CTX_DAG_OWNER='Group_9' AIRFLOW_CTX_DAG_ID='MLOP_pro' AIRFLOW_CTX_TASK_ID='create_newfile_task' AIRFLOW_CTX_EXECUTION_DATE='2024-04-19T02:17:29.741995+00:00' AIRFLOW_CTX_TRY_NUMBER='1' AIRFLOW_CTX_DAG_RUN_ID='manual__2024-04-19T02:17:29.741995+00:00'
[2024-04-19T02:17:49.277+0000] {taskinstance.py:1937} ERROR - Task failed with exception
Traceback (most recent call last):
  File "/home/airflow/.local/lib/python3.8/site-packages/airflow/operators/python.py", line 192, in execute
    return_value = self.execute_callable()
  File "/home/airflow/.local/lib/python3.8/site-packages/airflow/operators/python.py", line 209, in execute_callable
    return self.python_callable(*self.op_args, **self.op_kwargs)
  File "/opt/airflow/dags/src/create.py", line 11, in create_newfile
    with xw.App(visible=False) as app:
  File "/home/airflow/.local/lib/python3.8/site-packages/xlwings/main.py", line 311, in __init__
    self.impl = engines.active.apps.add(
AttributeError: 'NoneType' object has no attribute 'apps'
[2024-04-19T02:17:49.284+0000] {taskinstance.py:1400} INFO - Marking task as FAILED. dag_id=MLOP_pro, task_id=create_newfile_task, execution_date=20240419T021729, start_date=20240419T021749, end_date=20240419T021749
[2024-04-19T02:17:49.291+0000] {standard_task_runner.py:104} ERROR - Failed to execute job 7 for task create_newfile_task ('NoneType' object has no attribute 'apps'; 147)
[2024-04-19T02:17:49.335+0000] {local_task_job_runner.py:228} INFO - Task exited with return code 1
[2024-04-19T02:17:49.370+0000] {taskinstance.py:2778} INFO - 0 downstream tasks scheduled from follow-on schedule check
